Traceback (most recent call last):
, line 21, in f
ValueError: 1

